I0219 13:19:32.753983 140228892704768 run_training_v2.py:110] Running on cuda, with the following arguments:
I0219 13:19:32.754109 140228892704768 run_training_v2.py:112] {'board_size': 9, 'stack_history': 4, 'num_res_blocks': 6, 'num_planes': 64, 'replay_capacity': 100000, 'min_replay_size': 20000, 'batch_size': 128, 'learning_rate': 0.002, 'lr_decay': 0.1, 'lr_decay_milestones': [200000, 600000], 'num_train_steps': 1000000, 'argument_data': True, 'num_actors': 4, 'num_simulations': 240, 'parallel_leaves': 8, 'c_puct_base': 19652.0, 'c_puct_init': 1.25, 'temp_begin_value': 1.0, 'temp_end_value': 0.01, 'temp_decay_steps': 30, 'train_delay': 0.6, 'initial_elo': 0.0, 'checkpoint_frequency': 1000, 'checkpoint_dir': 'checkpoints/gomoku_v2', 'load_checkpoint_file': '', 'train_csv_file': 'logs/train_gomoku_v2.csv', 'eval_csv_file': 'logs/eval_gomoku_v2.csv', 'seed': 1}
I0219 13:19:33.290528 140225028281920 pipeline_v1.py:455] Start data collector thread
I0219 13:19:33.291022 140225019889216 pipeline_v2.py:103] Start training thread
I0219 13:19:33.978653 140230193967104 pipeline_v1.py:89] Start self-play actor 1
I0219 13:19:33.982455 140050109591552 pipeline_v1.py:89] Start self-play actor 3
I0219 13:19:33.983438 139730013667328 pipeline_v1.py:89] Start self-play actor 0
I0219 13:19:33.988883 140248478027776 pipeline_v2.py:216] Start evaluator
I0219 13:19:34.004069 140545075695616 pipeline_v1.py:89] Start self-play actor 2
Process Process-4:
Traceback (most recent call last):
  File "/usr/lib/python3.10/multiprocessing/process.py", line 314, in _bootstrap
    self.run()
  File "/usr/lib/python3.10/multiprocessing/process.py", line 108, in run
    self._target(*self._args, **self._kwargs)
  File "/home/michael/alpha_zero/alpha_zero/pipeline_v1.py", line 132, in run_self_play
    uniform_pi_prob = np.ones(pi_prob)
  File "/home/michael/.local/lib/python3.10/site-packages/numpy/core/numeric.py", line 204, in ones
    a = empty(shape, dtype, order)
ValueError: maximum supported dimension for an ndarray is 32, found 81
Process Process-6:
Traceback (most recent call last):
  File "/usr/lib/python3.10/multiprocessing/process.py", line 314, in _bootstrap
    self.run()
  File "/usr/lib/python3.10/multiprocessing/process.py", line 108, in run
    self._target(*self._args, **self._kwargs)
  File "/home/michael/alpha_zero/alpha_zero/pipeline_v1.py", line 132, in run_self_play
    uniform_pi_prob = np.ones(pi_prob)
  File "/home/michael/.local/lib/python3.10/site-packages/numpy/core/numeric.py", line 204, in ones
    a = empty(shape, dtype, order)
ValueError: maximum supported dimension for an ndarray is 32, found 81
Process Process-5:
Traceback (most recent call last):
  File "/usr/lib/python3.10/multiprocessing/process.py", line 314, in _bootstrap
    self.run()
  File "/usr/lib/python3.10/multiprocessing/process.py", line 108, in run
    self._target(*self._args, **self._kwargs)
  File "/home/michael/alpha_zero/alpha_zero/pipeline_v1.py", line 132, in run_self_play
    uniform_pi_prob = np.ones(pi_prob)
  File "/home/michael/.local/lib/python3.10/site-packages/numpy/core/numeric.py", line 204, in ones
    a = empty(shape, dtype, order)
ValueError: maximum supported dimension for an ndarray is 32, found 81
Process Process-3:
Traceback (most recent call last):
  File "/usr/lib/python3.10/multiprocessing/process.py", line 314, in _bootstrap
    self.run()
  File "/usr/lib/python3.10/multiprocessing/process.py", line 108, in run
    self._target(*self._args, **self._kwargs)
  File "/home/michael/alpha_zero/alpha_zero/pipeline_v1.py", line 132, in run_self_play
    uniform_pi_prob = np.ones(pi_prob)
  File "/home/michael/.local/lib/python3.10/site-packages/numpy/core/numeric.py", line 204, in ones
    a = empty(shape, dtype, order)
ValueError: maximum supported dimension for an ndarray is 32, found 81
